<?xml version="1.0"?>

<robot name="barrera">

    <material name="red">
        <color rgba="0.8 0 0 1" />
    </material>

    <link name="body_barrera">

        <inertial>
            <origin xyz="0 0 0.1" />
            <mass value="10000.0" />
            <inertia ixx="1.0" ixy="0.0" ixz="0.0"
            iyy="1.0" iyz="0.0" izz="1.0" />

        </inertial>
        <visual>        
            <origin xyz="0 0 0.1" />
            <geometry>
                <cylinder length="0.5" radius="0.05"/>
            </geometry>
            <material name="red"/>
        </visual>

        <collision>
            <origin xyz="0 0 0.1" />
            <geometry>
                <cylinder length="0.5" radius="0.08"/>
            </geometry>
        </collision>
    </link>

     <link name="brazo_barrera">

        <inertial>
            <origin xyz="-0.65 0 0.05" />
            <mass value="5.0" />
            <inertia ixx="2.5" ixy="0.0" ixz="0.0"
            iyy="0.0" iyz="0.0" izz="2.5" />

        </inertial>
        <visual>        
            <origin xyz="-0.65 0 0.05" />
            <geometry>
                <box size="2 0.08 0.08" />
            </geometry>
            <material name="red"/>
        </visual>

        <collision>
            <origin xyz="-0.65 0 0.05" />
            <geometry>
                <box size="2 0.08 0.08" />
            </geometry>
        </collision>
    </link>

     <joint name="barrier" type="revolute">
        <parent link="body_barrera" />
        <child link="brazo_barrera" />
        <dynamics damping="0.0" friction="0.0" />
        <origin xyz="0 0 0.1" />
        <axis xyz="0 0 1" />

        <limit lower="-3.15" upper="3.15" effort="1.0" velocity="0.5" />
    </joint>
</robot>