<?xml version="1.0"?>

<robot name="rampa">

    <material name="blue">
        <color rgba="0 0 0.8 1" />
    </material>

    <link name="body_rampa">

        <inertial>
            <origin xyz="5 0 0.1" />
            <mass value="100.0" />
            <inertia ixx="1.0" ixy="0.0" ixz="0.0"
            iyy="1.0" iyz="0.0" izz="1.0" />

        </inertial>
        <visual>        
            <origin xyz="5 0 0.1" />
            <geometry>
                <box size="2 4 1.5" />
            </geometry>
            <material name="blue"/>
        </visual>

        <collision>
            <origin xyz="5 0 0.1" />
            <geometry>
             <box size="2 4 1.5" />
            </geometry>
        </collision>

    </link>

    <link name="rampa_front">

        <inertial>
            <origin xyz="5 -4 0.1" />
            <mass value="100.0" />
            <inertia ixx="1.0" ixy="0.0" ixz="0.0"
            iyy="1.0" iyz="0.0" izz="1.0" />

        </inertial>
        <visual>        
            <origin xyz="5 -4 0.1" />
            <geometry>
                <box size="2 3.354101966 0.1" />
            </geometry>
            <material name="blue"/>
        </visual>

        <collision>
            <origin xyz="5 -4 0.1" />
            <geometry>
             <box size="2 3.354101966 0.1" />
            </geometry>
        </collision>
    </link>

    <link name="rampa_back">

        <inertial>
            <origin rpy="0 0 0" xyz="5 4 0.1" />
            <mass value="100.0" />
            <inertia ixx="1.0" ixy="0.0" ixz="0.0"
            iyy="0.0" iyz="1.0" izz="0.0" />

        </inertial>
        <visual>        
            <origin rpy="0 0 0" xyz="5 4 0.1" />
            <geometry>
                <box size="2 3.354101966 0.1" />
            </geometry>
            <material name="blue"/>
        </visual>

        <collision>
            <origin rpy="0 0 0" xyz="5 4 0.1" />
            <geometry>
             <box size="2 3.354101966 0.1" />
            </geometry>
        </collision>

    </link>

    <joint name="front_to_body" type="revolute">
        <parent link="body_rampa" />
        <child link="rampa_front" />
        <dynamics damping="0.0" friction="0.00001" />
        <origin xyz="0 0.15 1.7" />
        <axis xyz="1 0 0" />

        <limit lower="-2" upper="2" effort="10.0" velocity="0.5" />
    </joint>

    <joint name="back_to_body" type="revolute">
        <parent link="body_rampa" />
        <child link="rampa_back" />
        <dynamics damping="0.0" friction="0.00001" />
        <origin xyz="0 -0.15 1.7" />
        <axis xyz="1 0 0" />

        <limit lower="-2" upper="2" effort="10.0" velocity="0.5" />
    </joint>

</robot>